Workbook

Sheet Instrucciones
A1: Cribado sistemático — Torddis
A3: Fecha de búsqueda: 20 de agosto de 2026
A4: Bases: Scopus, ACM Digital Library, IEEE Xplore, Web of Science, PubMed
A6: NATURALEZA DE ESTE CRIBADO
A8: Las decisiones de la hoja «Cribado» proceden de un primer paso automatizado basado en reglas,
A9: aplicado sobre el título, el resumen y las palabras clave de cada registro. Cada decisión lleva
A10: su motivo escrito en la columna «motivo_automatico».
A12: Este paso NO sustituye al cribado humano. PRISMA 2020 exige revisores nombrados. Antes de
A13: publicar debe verificarse, como mínimo:
A14: · los 29 registros marcados «Incluir», uno por uno;
A15: · los 390 marcados «Dudoso»;
A16: · una muestra aleatoria de los «Excluir», para estimar falsos negativos.
... A33: clínico, industrial, deporte, agrícola).

Sheet Cribado
A1: id | B1: decision_automatica | C1: motivo_automatico | D1: revisor_decision | E1: revisor_motivo | F1: score | G1: conceptos | H1: base | I1: tambien_en | J1: year | K1: doc_type | L1: authors | M1: title | N1: abstract | O1: venue | P1: keywords | Q1: doi | R1: etapa_revisor | S1: categoria_exclusion_elegibilidad
A2: 1 | B2: Incluir | C2: Cumple el alcance: población en edad escolar y contexto doméstico o de aprendizaje remoto | D2: Excluir | E2: Estudio cualitativo de realidad mixta; no detecta distraccion | F2: 7 | G2: distracción+niños+contexto+sensado+intervención+ambos en título | H2: Scopus | I2: Scopus | J2: 2025 | K2: ARTICLE | L2: Goagoses, Naska and Winschiers-Theophilus, Heike and Auala, Selma and Pope, Nicolas and Rötkönen, Erkki and Itenge, Helvi and Suero Montero, Calkin and Suovuo, Tomi and Sutinen, Erkki | M2: Teachers and Students Envisioning Mixed Reality Remote Learning: A Qualitative Exploration on Fostering Academic Engagement | N2: Mixed reality (MR) provides new opportunities and affordances for fostering student engagement in remote learning. The current qualitative case study set out to (1) explore teachers’ perspective of academic engagement in traditional classrooms, (2) explore how teachers’ and students’ envision engaging lessons using MR for remote learning, and (3) extrapolate limitations and affordances for the further development of MR for remote learning. Eight students and four teachers from a primary school in Namibia participated. Each participant wore the HoloLens 2, interacting with others who were live streamed from another room. Group interviews with the teachers revealed core practices and strategies focused on the centrality of students, student-teacher relationships, rewards and evaluations, and the physical environment for creating engagement in traditional classrooms. Teachers and students participated in role-plays centered around fostering emotional, behavioral, and agentic engagement in imagined lessons that used MR for live streaming from different locations. The role-playing teachers mainly used verbal practices and strategies for fostering closeness, as well as giving feedback and evaluations. However, many strategies previously named or found in the literature were not enacted and symbolic MR boundaries were crossed. Based on our results, we derived affordances and future directions for the further design and development of MR for remote learning. © The Author(s) 2024. | O2: Technology, Knowledge and Learning | P2: Adversarial machine learning; Augmented reality; Contrastive Learning; Educational technology; Federated learning; Mixed reality; Teaching; Academic engagement; Affordances; Hololens; Instructional practices; Mixed reality; Qualitative; Qualitative e | Q2: 10.1007/s10758-024-09797-4 | R2: Texto completo (grupos 1-2) | S2: (iii) no automatic sensing
A3: 2 | B3: Incluir | C3: Cumple el alcance: población en edad escolar y contexto doméstico o de aprendizaje remoto (menciona también educación superior: verificar) | D3: Excluir | E3: Aprendizaje sincrono en educacion superior | F3: 6 | G3: distracción+niños+sensado+intervención+ambos en título | H3: IEEE | I3: IEEE|Scopus|WoS | J3: 2022 | K3: INPROCEEDINGS | L3: Godly, Cinthia Joy and Balasubramanian, Venki and Stranieri, Andrew and Saikrishna, Vidya and Mohammed, Rehena Sulthana and Chackappan, Godly | M3: Deep learning model to empower student engagement in online synchronous learning environment | N3: Following the start of the pandemic, online synchronous learning has grown significantly. The higher education sector is searching for new creative ways to provide the information online because of the switch from face-to-face to online synchronous course delivery. Students are also becoming accustomed to studying online, and research has shown that synchronous online learning has a variety of effects on student engagement. For instance, according to statistics from the National Survey of Student Engagement, students are less likely to participate in collaborative learning, studentfaculty interactions, and conversations when learning online if they use quantitative reasoning during face-to-face instruction. Additionally, studies suggest that because they depend on their devices to take online classes, students feel more alienated from their lecturers. This has been linked to a drop in contacts with peers and teachers as a result. By using a cutting-edge deep learning model to predict learner engagement behaviour in a synchronous teaching environment, our research intends to improve online engagement. The model with a clever trigger will encourage the disengaged pupils to communicate with the teachers online. Smart triggers will be built around factors that have been found, focusing on disengaged students to engage them in real-time with automatic, personalized feedback. © 2022 IEEE. | O3: 2022 IEEE 19th India Council International Conference (INDICON) | P3: Deep learning;Learning management systems;Pandemics;Navigation;Education;Switches;Oral communication;Deep learning model;online synchronous learning;Learner engagement;Personalized feedback;Interaction Quality (IoQ) factors | Q3: 10.1109/indicon56171.2022.10040191 | R3: Texto completo (grupos 1-2) | S3: (i) population not of school age
A4: 3 | B4: Incluir | C4: Cumple el alcance: población en edad escolar y contexto doméstico o de aprendizaje remoto (menciona también educación superior: verificar) | D4: Excluir | E4: Media de edad 20 anos; poblacion universitaria | F4: 6 | G4: distracción+niños+contexto+sensado+ambos en título | H4: IEEE | I4: IEEE|Scopus | J4: 2022 | K4: INPROCEEDINGS | L4: Purushottama Rao, K and Janet, B | M4: Teacher Assistance System to Detect Distracted Students in Online Classroom Environment | N4: Perceiving students' engagement accurately is important for teachers and educational institutions, especially in online classrooms. In this paper, we address the problem of automated detection of distracted students from videos recorded in online classroom environment. To tackle this difficult challenge, we propose a Teacher Assistance System that detects inattentive students using their head pose from video data. We gathered data in two sessions by using Google Meet and WebEx portals to conduct online classes for a group of nineteen undergraduate Computer Science students. The authors used the OpenCV Caffe model to detect the faces. We used the Perspective-n-Problem approach to estimate the head pose of all the pupils in the class, and we also used the distance between the nose tip and the chin point to improve the model's accuracy. In an online classroom environment, the proposed system detected distracted pupils with 90.45% accuracy. The proposed Teacher Assistance System is precise and does not demand the use of any advanced tools. As a result, it might be used in both online and offline classroom scenarios, as well as other places where people who are distracted need to be identified. © 2022 IEEE | O4: 2022 4th International Conference on Smart Systems and Inventive Technology (ICSSIT) | P4: Computer science;Computational modeling;Nose;Magnetic heads;Internet;Pupils;Task analysis;Students' Engagement;Distracted Students;Face Detection;Head Pose Estimation;Deep Learning;Teacher Assistance System;Computer Vision | Q4: 10.1109/icssit53264.2022.9716406 | R4: Texto completo (grupos 1-2) | S4: (i) population not of school age
A5: 4 | B5: Incluir | C5: Cumple el alcance: población en edad escolar y contexto doméstico o de aprendizaje remoto (menciona también educación superior: verificar) | D5: Excluir | E5: Revision sistematica, no estudio primario | F5: 6 | G5: distracción+niños+sensado+intervención+ambos en título | H5: Scopus | I5: Scopus | J5: 2026 | K5: CONFERENCE | L5: Jacob, Thomson Kurian and Mandal, Lopa | M5: A Systematic Review of Generative AI Architectures for Emotion Adaptive Personalized Learning: Impact on Student Outcomes, Motivation and Engagement | N5: Generative AI architecture employing emotion recognition shows promise for the future of personalized learning. Research has shown that multimodal systems (combining facials, voice, biometrics, text) with deep learning, reinforcement learning and Intelligent Tutoring Systems (ITS) support positive academic achievement and engagement in K12 and Higher Education; although there may be other effects such as increased motivation in specific students. These types of adaptive systems provide real-time feedback through closed-loop mechanisms, allowing both cognitive and emotional needs of students to be met through instruction provided in real time. This review looks at how Generative AI has affected development of emotion detection within adaptive forms of digital learning and their relationship to academic progress and student emotions toward online education. © 2026 IEEE. | O5: 2026 9th International Conference on Electronics, Materials Engineering and Nano-Technology, IEMENTech 2026 | P5: Cognitive systems; Computer aided instruction; Deep learning; E-learning; Education computing; Educational technology; Emotion Recognition; Engineering education; Learning systems; Motivation; Online systems; Psychology computing; Real time systems; | Q5: 10.1109/iementech202669403.2026.11434057 | R5: Texto completo (grupos 1-2) | S5: (v) no primary peer-reviewed study / no DOI
A6: 5 | B6: Incluir | C6: Cumple el alcance: población en edad escolar y contexto doméstico o de aprendizaje remoto | D6: Incluir | E6: Alumnado de primaria; aprendizaje en linea; identificacion automatica de estados de baja atencion sobre video de webcam de 24 participantes | F6: 6 | G6: distracción+niños+sensado+intervención+ambos en título | H6: Scopus | I6: Scopus|WoS | J6: 2024 | K6: ARTICLE | L6: Kim, Suhye and Kim, Jung-Hwan and Hyung, Wooseok and Shin, Suhkyung and Choi, Myoung Jin and Kim, Dong Hwan and Im, Chang-Hwan | M6: Characteristic Behaviors of Elementary Students in a Low Attention State During Online Learning Identified Using Electroencephalography | N6: With the widespread application of online education platforms, the necessity for identifying learners' mental states from webcam videos is increasing as it can be potentially applied to artificial intelligence-based automatic identification of learner states. However, the behaviors that elementary school students frequently exhibit during online learning particularly when they are in a low attention state have rarely been investigated. This study employed electroencephalography (EEG) to continuously track changes in the learner's attention state during online learning. A new EEG index reflecting elementary students' attention level was developed using an EEG dataset acquired from 34th graders during a computerized d2 test of attention. Characteristic behaviors of 24 elementary students in a low attention state were then identified from the webcam videos showing their upper bodies captured during 40-min online lectures, with the proposed EEG index being used as a reference to determine their attention level at the time. Various characteristic behaviors were identified regarding the participant's mouth, head, arms, and torso. For example, opening the mouth or leaning back was observed more frequently in a low-attention state than in a high-attention state. It is expected that the characteristic behaviors reflecting a learner's low attention state would be utilized as a useful reference in developing more interactive and effective online education systems. © 2008-2011 IEEE. | O6: IEEE Transactions on Learning Technologies | P6: Automation; Behavioral research; Computer aided instruction; E-learning; Electrophysiology; Job analysis; Online systems; Statistical tests; Students; Adaptive learning; Attention monitoring; Behavioral science; Distance-learning; Index; Intelligent | Q6: 10.1109/tlt.2023.3289498 | R6: Texto completo (grupos 1-2)
A7: 6 | B7: Incluir | C7: Cumple el alcance: población en edad escolar y contexto doméstico o de aprendizaje remoto | D7: Excluir | E7: Engagement medido por observacion humana, no automatica | F7: 6 | G7: distracción+niños+contexto+sensado+ambos en título | H7: Scopus | I7: Scopus|WoS | J7: 2015 | K7: ARTICLE | L7: Mulqueeny, Kevin and Kostyuk, Victor and Baker, Ryan S. and Ocumpaugh, Jaclyn | M7: Incorporating effective e-learning principles to improve student engagement in middle-school mathematics | N7: Background: The expanded use of online and blended learning programs in K-12 STEM education has led researchers to propose design principles for effective e-learning systems. Much of this research has focused on the impact on learning, but not how instructional design impacts student engagement, which has a critical impact both on short-term learning and long-term outcomes. Reasoning Mind has incorporated the e-learning principles of personalization, modality, and redundancy into the design of their next-generation blended learning platform for middle-school mathematics, named Genie 3. In three studies, we compare student engagement with the Genie 3 platform to its predecessor, Genie 2, and to traditional classroom instruction. Results: Study 1 found very high levels of student engagement with the Genie 2 platform, with 89 % time on-task and 71 % engaged concentration. Study 2 found that students using Genie 3 spent significantly more time in independent on-task behavior and less time off-task or engaged in on task conversation with peers than students using Genie 2. Students using Genie 3 also showed more engaged concentration and less confusion. Study 3 found that students using Genie 3 spent 93 % of their time on-task, compared to 69 % in traditional classrooms. They also showed more engaged concentration and less boredom and confusion. Genie 3 students sustained their engagement for the entire class period, while engagement in the traditional classroom dropped off later in the class session. In both study 2 and 3, Genie 3 students showed more growth from pre- to post-test on an assessment of key concepts in sixth-grade mathematics. Conclusions: The incorporation of evidence-based e-learning principles into the design of the Genie 3 platform resulted in higher levels of student engagement when compared to an earlier, well-established platform that lacked those principles, as well as when compared to traditional classroom instruction. Increased personalization, th | O7: International Journal of STEM Education | Q7: 10.1186/s40594-015-0028-6 | R7: Texto completo (grupos 1-2) | S7: (iii) no automatic sensing
A8: 7 | B8: Incluir | C8: Cumple el alcance: población en edad escolar y contexto doméstico o de aprendizaje remoto | D8: Excluir | E8: Primaria, pero sin sensor: predice engagement con datos de la plataforma en linea | F8: 6 | G8: distracción+niños+contexto+sensado+ambos en título | H8: Scopus | I8: Scopus | J8: 2021 | K8: CONFERENCE | L8: Wang, Kunyu and Zuo, Mingzhang and Yu, Shuqiao and Luo, Heng and Yan, Yujie and Ouyang, Hongjie | M8: Use Machine Learning to Predict Primary School Students Level of Learning Engagement | N8: As online learning develops an increasingly important role in education, learning engagement becomes increasingly important. There are three dimensions of learning engagement: behavioral engagement, cognitive engagement, and emotional engagement. To better understand the impact of the three dimensions of engagement on the overall engagement in the fully online situation, this study uses machine learning algorithms to explore the importance rank of three dimensions of learning engagement and the accuracy of four different machine learning algorithms in predicting students engagement. We investigated 3172 primary school students in Hubei Province with a distance learning engagement scale. The results show that emotional engagement is the major contributor to fully online learning. In the case of predicting Engagement, SVM is more accurate than other algorithms. © 2021 Association for Computing Machinery. All rights reserved. | O8: ACM International Conference Proceeding Series | P8: E-learning; Learning algorithms; Machine learning; Students; Emotional engagements; Engagement; Machine learning algorithms; Machine-learning; Online learning; Primary schools; School students; Student levels; SVM; Three dimensions; Forecasting | Q8: 10.1145/3510309.3510313 | R8: Texto completo integro (resolucion de dudosos) | S8: (iii) no automatic sensing
A9: 8 | B9: Incluir | C9: Cumple el alcance: población en edad escolar y contexto doméstico o de aprendizaje remoto | D9: Incluir | E9: 159 participantes de 7 a 10 anos; clases de ingles en linea desde el hogar; medicion automatica de exposicion facial como indicador de atencion | F9: 6 | G9: distracción+niños+sensado+intervención+ambos en título | H9: WoS | I9: WoS | J9: 2023 | K9: Article | L9: Xu, XQ; Dugdale, DM; Wei, X; Mi, WJ | M9: Leveraging Artificial Intelligence to Predict Young Learner Online Learning Engagement | N9: The recent surge of online language learning services in the past decade has benefitted second language learners. However, there is a lack of understanding of whether learners, especially young learners, are engaged in online learning, and how educators can enhance the engagement of the online learning experience. This study examines an artificial intelligence (Al)- powered automated system that uses voice and facial recognition to track both teacher and learner speech, facial expressions, and interactions in real-time in a one-to-one 25-minute online English class. Each learner completed a learner engagement survey within 72 hours of the online class. Results demonstrated that young learners were highly engaged during this one-to-one online learning setting (mean = 4.5, out of 5). Learners' frontal face exposure (indicating their attentiveness during class) and English proficiency levels are significant and positive predictors of learner engagement. Teachers' total length of speech and instructional time tended toward significance in predicting learner engagement. Educational implications are discussed. | O9: AMERICAN JOURNAL OF DISTANCE EDUCATION | Q9: 10.1080/08923647.2022.2044663 | R9: Texto completo (grupos 1-2)
A10: 9 | B10: Incluir | C10: Cumple el alcance: población en edad escolar y contexto doméstico o de aprendizaje remoto | D10: Excluir | E10: Propuesta conceptual sin evaluacion con participantes | F10: 5 | G10: distracción+niños+contexto+sensado+intervención | H10: IEEE | I10: IEEE|Scopus | J10: 2023 | K10: INPROCEEDINGS | L10: Saravanan, Abhinaya and Samuel Azariya, S. David and Soms, Nisha and Shyam, Archana | M10: EduVigil: Shaping the Future of Education with AI - An Intriguing Case Study | N10: The rapid transition towards digital classrooms underlines the urgent need for advanced tools to optimize learning experiences. This paper presents EduVigil, a comprehensive multi-modal AI-based system that pioneers real-time monitoring of classrooms. Our approach uniquely leverages a custom dataset tailored to emulate a realistic classroom environment, featuring children in varying states of attention, pose, gesture, and presence. Utilizing this rich dataset, EduVigil incorporates a diverse set of features including facial recognition, attention tracking, pose and gesture recognition, attendance management, real-time alert system, sentiment analysis, automatic speech recognition, voice detection, behavior prediction, Chatbot integration, automatic summarization, and real-time translation. The display of these remarkable attributes is predicated on the deployment of state-of-the-art AI techniques. These include Convolutional Neural Networks (CNNs), a powerful tool for decoding visual data patterns; Long Short-Term Memory networks (LSTMs), specifically designed for scrutinizing sequential data; sophisticated pose estimation algorithms, engineered to accurately locate body positions; and the lightning-fast YOLO (You Only Look Once) algorithm, a crucial asset for swift object identification tasks. Additionally, the system employs sophisticated AI techniques including automatic speech recognition using models like Mozilla's DeepSpeech, real-time translation using the Transformer model, and automatic summarization inspired by Liu and Lapata's extractive model, to enable effective speech recognition, translation, and summarization in digital classrooms. A case study involving teacher and parent surveys indicates a strong acceptance rate of 90 percent, confirming the potential impact of EduVigil in real classroom scenarios. This promising acceptance highlights its capacity to enhance student engagement, automate administrative tasks, and provide real-time insights that fac | O10: 2023 14th International Conference on Computing Communication and Networking Technologies (ICCCNT) | P10: Surveys;Visualization;Sentiment analysis;Education;Transformers;Real-time systems;Artificial intelligence;AI in Education;EduVigil;Multi-modal Learning System;AI-Enabled Classroom;Facial Recognition;Attention Tracking;Behavior Analysis;Automatic Spee | Q10: 10.1109/icccnt56998.2023.10307866 | R10: Texto completo (grupos 1-2) | S10: (iii) no automatic sensing
A11: 10 | B11: Incluir | C11: Cumple el alcance: población en edad escolar y contexto doméstico o de aprendizaje remoto | D11: Excluir | E11: Tutoria de literatura; no aborda distraccion ni sensado | F11: 5 | G11: distracción+niños+intervención+ambos en título | H11: Scopus | I11: Scopus | J11: 2025 | K11: CONFERENCE | L11: Ronald Hadrian, D. and Caroline, Deepa and Niveditha, R. and Yazhini, V. and Mahalakshmi, L. and Gracy Nirmala, J. | M11: AI-Driven Tutoring in English Literature: Fostering Deeper Interpretation and Student Engagement | N11: This study shows a novel technique to teach English writing with AI. People are the focus of the multi-level structure. It improves pupils' literary reading, comprehension, and analysis. Language, cognitive, and emotional development are included. Great teachers employ constructive criticism and interpretive reasoning. Most AI-based education systems focus on text analytics, but our paradigm emphasizes context and emotional connections. Learning is more fun and engaging. Vector-based modeling, semantic clustering, and reward-driven feedback improve reading. Affective computing helps the system adjust voice, style, and speed based on how the learner feels, such as joyful, curious, or concentrated. This model outperforms others in twelve key categories, including cognitive depth, emotional intelligence, contextual awareness, and input correctness, according to studies. The method produces more uniform interpretations, speedier analysis, and happier pupils. This study examines how combining AI with humanistic education alters AI-assisted learning. Along with training technical skills, it examines how AI might increase critical thinking, empathy, and long-term motivation. The framework is flexible, recognizes human feelings, and encourages intellectual growth. This advances English literature instruction greatly. © 2025 IEEE. | O11: 2025 IEEE 5th International Conference on ICT in Business Industry and Government, ICTBIG 2025 | P11: Computer aided instruction; E-learning; Education computing; Emotional intelligence; Feedback; Learning systems; Personnel training; Semantics; Students; Teaching; Adaptive learning; Emotional feedback; English literature; Literature education; Perso | Q11: 10.1109/ictbig68706.2025.11323730 | R11: Texto completo (grupos 1-2) | S11: (iv) distraction not addressed
A12: 11 | B12: Incluir | C12: Cumple el alcance: población en edad escolar y contexto doméstico o de aprendizaje remoto (menciona también educación superior: verificar) | D12: Excluir | E12: Prediccion de exito con datos de plataforma; sin sensado ni ninos | F12: 5 | G12: distracción+niños+sensado+ambos en título | H12: Scopus | I12: Scopus | J12: 2026 | K12: CONFERENCE | L12: Ajibade, Samuel-Soma M. and Velos, Mary Angelie P. and Ypanto, Leomar A. and Legaspino, Rosie Fe B. and Mabanto, Jina Marie R. and Villagonzalo, Mersin C. and Cababat, Feliciana G. and Dayupay, Johnry P. | M12: Ensemble Learning Techniques to Predict Student Success Based on Online Engagement Patterns in a Virtual Learning Environment | N12: Virtual Learning Environments (VLEs) have changed higher education by giving students easy, flexible, and digital access to all of their learning materials. By looking at how engaged students are on these platforms, we can better understand how well they are doing in school and help students who are at danger. Even though there is a lot of VLE data available, many schools have trouble using it to make accurate early predictions about how well kids will do, which makes it harder to help students who are at danger of failing. This project seeks to forecast academic performance by analyzing online interaction patterns from the Open University Learning Analytics Dataset (OULAD), utilizing machine learning to pinpoint significant factors and facilitate early interventions. The OULAD dataset, which comes from the UCI Machine Learning Repository, has anonymous student engagement measures like how often they log in, how much time they spend on VLE, how often they post in forums, and how many assignments they turn in. Python libraries like Pandas, Scikit-learn, and Seaborn have been used to create machine learning models including logistic regression, decision trees, and random forests for data preprocessing, modeling, and visualization. Initial findings indicate that persistent early-term engagement, especially frequent logins and assignment submissions, is a substantial predictor of superior academic performance, whereas irregular engagement is associated with diminished grades. These findings empower instructors to execute tailored interventions, enhancing retention and individualizing the learning experience. Subsequent study may amalgamate multimodal data to fortify model resilience across various educational settings. © 2026 IEEE. | O12: Proceedings - 2026 18th International Conference on Electronics, Computer, and Computation, ICECCO 2026 | P12: Computer aided instruction; Data visualization; Digital libraries; E-learning; Education computing; Federated learning; Forecasting; Forestry; Learning systems; Logistic regression; Machine learning; Random forests; Students; Virtual reality; Academi | Q12: 10.1109/icecco67619.2026.11488800 | R12: Texto completo (grupos 1-2) | S12: (iii) no automatic sensing
A13: 12 | B13: Incluir | C13: Cumple el alcance: población en edad escolar y contexto doméstico o de aprendizaje remoto | D13: Excluir | E13: Participantes de 19 a 43 anos (docentes en formacion) | F13: 5 | G13: distracción+niños+contexto+ambos en título | H13: Scopus | I13: Scopus|WoS | J13: 2025 | K13: ARTICLE | L13: Zagami, Jason | M13: Virtual maker spaces: Enhancing student engagement through extended reality in the Co-creation of learning spaces | N13: This study investigates the integration of virtual reality (VR) platforms, CoSpaces and Minecraft, and artificial intelligence (AI) tools into primary school technology education courses, focusing on their role in virtual maker spaces. With a quasi-experimental design, 140 pre-service teachers engaged in designing and using virtual classroom spaces, alternating between CoSpaces and Minecraft to examine the strengths of each platform. Virtual maker spaces served as collaborative environments where participants explored creative classroom layouts, instructional strategies, and the application of constructivist and situated learning theories. Findings revealed significant improvements in pedagogical confidence and understanding, with Minecraft excelling in fostering creativity and complex designs, while CoSpaces facilitated rapid prototyping and interactivity. High engagement and collaboration scores underscore the value of virtual maker spaces in simulating real-world teaching scenarios. Regression analysis identified self-efficacy as a key predictor of success, and rubric evaluations highlighted the educational relevance and innovation in virtual classroom designs. This research contributes to the growing discourse on immersive technologies in teacher education, providing actionable insights into the use of virtual maker spaces to prepare future educators for technology-rich classrooms. © 2025 | O13: Computers and Education: X Reality | Q13: 10.1016/j.cexr.2025.100115 | R13: Texto completo (grupos 1-2) | S13: (i) population not of school age
A14: 13 | B14: Incluir | C14: Cumple el alcance: población en edad escolar y contexto doméstico o de aprendizaje remoto | D14: Excluir | E14: Aprendizaje gamificado en TDAH; sin sensado automatico | F14: 4 | G14: distracción+niños+sensado+intervención | H14: ACM | I14: ACM | J14: 2024 | K14: inproceedings | L14: Ariyasena, Prathibha Sathyanjalee and Munasinghe, Nimthara Nuwangi Bandara and Chandra, Christan Fryer Cooraydas and Dissanayake, Prashanthi Anushika and Samarakoon, Uthpala and Tissera, Wishalya | M14: Exploring the Utility of Gamified Learning to Support Academic Progress among ADHD-Diagnosed Children | N14: Attention-deficit/hyperactivity disorder (ADHD) is one of the most prevalent mental diseases affecting children. ADHD symptoms include impulsivity (rash, unpredictable behavior), hyperactivity (excessive movement that is inappropriate for the setting), and inattention (inability to concentrate). ADHD can have a wide-ranging impact on a person's life, including academic and career achievement, interpersonal relationships, and daily functioning. ADHD is considered a chronic and disabling disorder. It was further divided into three distinct types: inattentiveness, hyperactivity-impulsivity, and a combination of the two, each needing a unique approach to learning and skill development. While various research has been conducted on the use of the SNAP-IV to identify children with ADHD in Sri Lanka and the challenges they face, there is a huge knowledge gap in the creation of effective learning solutions for Sri Lankan children diagnosed with ADHD. Parents required to complete the SNAP IV questionnaire via a web application is critical for effective intervention. A machine learning model integrated into the system analyzes the responses to identify specific ADHD subtypes. Subsequently, personalized mobile games were created to cater to the individual cognitive needs of each child. These games encompass exercises aimed at building focus, managing impulsivity, improving memory, and improving time management skills. This comprehensive approach, intertwining assessment, personalization, and academic enrichment within a gamified framework, seeks to offer a tailored and engaging solution for ADHD-diagnosed children. By addressing cognitive challenges and promoting academic growth, the research aims to contribute valuable insights into the effectiveness of gamified interventions for children with ADHD, specifically in the Sri Lankan context. | O14: Proceedings of the 2024 Sixteenth International Conference on Contemporary Computing | P14: ADHD, Academic progress, Gamification, Mobile Application, SNAP IV | Q14: 10.1145/3675888.3676047 | R14: Texto completo (grupos 1-2) | S14: (iii) no automatic sensing
A15: 14 | B15: Incluir | C15: Cumple el alcance: población en edad escolar y contexto doméstico o de aprendizaje remoto | D15: Excluir | E15: Evaluacion clinica de TDAH con realidad virtual | F15: 4 | G15: distracción+niños+contexto+sensado | H15: IEEE | I15: IEEE|PubMed|Scopus|WoS | J15: 2020 | K15: ARTICLE | L15: Yeh, Shih-Ching and Lin, Sheng-Yang and Wu, Eric Hsiao-Kuang and Zhang, Kai-Feng and Xiu, Xu and Rizzo, Albert and Chung, Chia-Ru | M15: A Virtual-Reality System Integrated With Neuro-Behavior Sensing for Attention-Deficit/Hyperactivity Disorder Intelligent Assessment | N15: Attention-deficit/Hyperactivity disorder(ADHD) is a common neurodevelopmental disorder among children. Traditional assessment methods generally rely on behavioral rating scales (BRS) performed by clinicians, and sometimes parents or teachers. However, BRS assessment is time consuming, and the subjective ratings may lead to bias for the evaluation. Therefore, the major purpose of this study was to develop a Virtual Reality (VR) classroom associated with an intelligent assessment model to assist clinicians for the diagnosis of ADHD. In this study, an immersive VR classroom embedded with sustained and selective attention tasks was developed in which visual, audio, and visual-audio hybrid distractions, were triggered while attention tasks were conducted. A clinical experiment with 37 ADHD and 31 healthy subjects was performed. Data from BRS was compared with VR task performance and analyzed by rank-sum tests and Pearson Correlation. Results showed that 23 features out of total 28 were related to distinguish the ADHD and non-ADHD children. Several features of task performance and neuro-behavioral measurements were also correlated with features of the BRSs. Additionally, the machine learning models incorporating task performance and neuro-behavior were used to classify ADHD and non-ADHD children. The mean accuracy for the repeated cross-validation reached to 83.2%, which demonstrated a great potential for our system to provide more help for clinicians on assessment of ADHD. © 2001-2011 IEEE. | O15: IEEE Transactions on Neural Systems and Rehabilitation Engineering | P15: Task analysis;Pediatrics;Machine learning;Medical services;Virtual environments;Computer science;Medical diagnostic imaging;Attention deficit and hyperactivity disorder;virtual reality;neuro-behavior;machine learning;assessment | Q15: 10.1109/tnsre.2020.3004545 | R15: Texto completo (grupos 1-2) | S15: (iv) distraction not addressed
A16: 15 | B16: Incluir | C16: Cumple el alcance: población en edad escolar y contexto doméstico o de aprendizaje remoto | D16: Excluir | E16: Integracion con instruccion presencial en aula, no hogar; propuesta de sistema sin participantes ni estudio empirico | F16: 4 | G16: distracción+niños+contexto+sensado | H16: IEEE | I16: IEEE|Scopus | J16: 2025 | K16: INPROCEEDINGS | L16: Shanmugalingam, Nithiyasagar and Maheshwaran, Liseyanth and Rizvee, Imana and RJ, Roshni and Samarakoon, Uthpala and Rajendran, Karthiga | M16: EDU-SENSE: AI-Driven Adaptive E-Learning System for Primary Education | N16: This research addresses critical gaps in primary education by integrating AI-driven e-learning tools with traditional classroom teaching, ensuring technology supports rather than replaces teachers while improving student learning outcomes. In getting ready for high-pressure exams like Sri Lanka's Grade 5 Scholarship Examination, maintaining student engagement and emotional well-being remains a significant challenge. EDU-SENSE is an AI-driven web platform designed for primary education that integrates personalized content delivery, stress detection, and an emotion-aware chatbot. The system begins with a diagnostic pre-test to assess individual skill levels,and provides syllabus-aligned questions, and delivers targeted revision based on identified knowledge gaps. A s tress-aware module and motivational chatbot provide emotional support, while peer collaboration features promote teamwork and knowledge sharing. Using Machine Learning, Natural Language Processing, and fine-tuned Large Language Models, EDU-SENSE offers a holistic solution that enhances both academic performance and emotional well-being in young learners. © 2025 IEEE. | O16: 2025 7th International Conference on Advancements in Computing (ICAC) | P16: Electronic learning;Adaptive systems;Scholarships;Large language models;Education;Anxiety disorders;Machine learning;Chatbots;Teamwork;Large Language Models;Natural Language Processing;Stress detection;Peer collaboration;Machine learning | Q16: 10.1109/icac69156.2025.11361431 | R16: Texto completo integro (resolucion de dudosos) | S16: (ii) setting not domestic or remote
A17: 16 | B17: Incluir | C17: Cumple el alcance: población en edad escolar y contexto doméstico o de aprendizaje remoto | D17: Excluir | E17: Educacion superior; encuesta de satisfaccion | F17: 4 | G17: distracción+niños+sensado+intervención | H17: IEEE | I17: IEEE | J17: 2023 | K17: INPROCEEDINGS | L17: Suganya, A. and Sheshasaayee, Ananthi | M17: Prediction of Student Perception Towards Current Educational Design Using Feature Selection and Machine Learning Techniques | N17: Student perception is a vital part of the educational process since it has a direct influence on motivation, engagement, and overall academic achievement. Prior to COVID-19, the majority of education had a traditional approach, therefore there were few factors that may affect the perception of students. However, there was a significant influence on educational perception during the outbreak of COVID-19, since education was entirely transformed into online learning and eventually into a hybrid form. Therefore, it is crucial for educational institutions to comprehend these characteristics in order to give pupils a nurturing and enriching atmosphere. The objective of the article is to identify the factor that has the highest influence on students’ perception of the current educational system. Feature analysis is used in identifying the parameter that plays a great role in perception levels. Based on the information gathered through questionnaires, machine learning methods are used to forecast the degree of student perception. Thus, this research enables educational institutions to make data-driven choices that enhance the overall learning environment. | O17: 2023 International Conference on the Confluence of Advancements in Robotics, Vision and Interdisciplinary Technology Management (IC-RVITM) | P17: COVID-19;Technology management;Education;Machine learning;Regression analysis;Pupils;Robots;feature selection;regression;student feedback student perception;education | Q17: 10.1109/ic-rvitm60032.2023.10435230 | R17: Texto completo (grupos 1-2) | S17: (i) population not of school age
A18: 17 | B18: Incluir | C18: Cumple el alcance: población en edad escolar y contexto doméstico o de aprendizaje remoto | D18: Excluir | E18: Aprendizaje con realidad aumentada; no aborda distraccion | F18: 4 | G18: distracción+niños+sensado+intervención | H18: Scopus | I18: Scopus | J18: 2018 | K18: CONFERENCE | L18: Mahmoudi, Maryam Tayefeh and Zeraati, Farnaz Zamiri and Yassini, Parham | M18: A Color Sensing AR-Based Interactive Learning System for Kids | N18: In the last decade, there has been a rapid growth in applying Augmented Reality (AR) and Internet of Things (IoT) as emerging technologies in linking physical and virtual objects for educational purposes. Realizing the complex concepts in a way that learner be able to interact with, will not only elevate the learning passion, but also has a significant positive role on learning performance and student's engagement. According to the aforementioned points, in this paper, we propose a color sensing AR-Based interactive learning system for kids which helps them to scan and explore the colors and learn their corresponding words in Spanish language. Our aim is to explore the role of such an AR-IoT-based system on students' learning performance. To do this, an embedded system including a color sensor and a raspberry pi board was implemented and provided for the kids. By placing the sensor on the specially designed colored book, the light's color frequency is measured and RGB code is sent over the cloud using MQTT protocol. On the web application side, color data is fetched from the cloud server and learners will be provided with a real-time feedback with the corresponding animations and multimedia content that teaches colors in Spanish language. Students' learning performance was assessed using paired t-test based upon the results of their pre-test and post-test, before and after interacting with the system. The successful experimental results were achieved proving the effectiveness of the system on learning performance. © 2018 IEEE. | O18: 12th National and the 6th International Conference on e-Learning and e-Teaching, ICELET 2018 | P18: Augmented reality; Color; E-learning; Educational technology; Internet of things; Students; Emerging technologies; Interactive learning; Interactive learning systems; Internet of Things (IOT); Learning performance; Multimedia contents; Real-time feed | Q18: 10.1109/icelet.2018.8586762 | R18: Texto completo (grupos 1-2) | S18: (iv) distraction not addressed
A19: 18 | B19: Incluir | C19: Cumple el alcance: población en edad escolar y contexto doméstico o de aprendizaje remoto | D19: Excluir | E19: Edad media 10,3 anos, pero el reconocimiento facial solo aparece como trabajo futuro; gamificacion sin sensado | F19: 4 | G19: distracción+niños+ambos en título | H19: Scopus | I19: Scopus|WoS | J19: 2023 | K19: ARTICLE | L19: Bachiri, Younes-Aziz and Mouncif, Hicham and Bouikhalene, Belaid | M19: Artificial Intelligence Empowers Gamification: Optimizing Student Engagement and Learning Outcomes in E-learning and MOOCs | N19: In this era of Artificial Intelligence (AI) growth, characterized by advances in the Large Language Models (LLMs) used by ChatGPT and Bard, this study examines the effects of gamification and Automatic Question Generation (AQG) on student engagement and learning outcomes in the context of a Massive Open Online Course (MOOC). AQG, implemented via a Moodle plugin, transforms conventional assessments into an interactive, gamified experience, leveraging the “test effect” to improve learning outcomes. Research with 100 fifth-graders in a primary and secondary school shows that gamified assessments significantly boost student motivation and learning outcomes compared with traditional methods. The custom Moodle plugin facilitates the AQG process, generating contextually relevant and grammatically correct Multiple-Choice Questions (MCQs) from course content. The result is a dynamic, personalized assessment experience aimed at optimizing student retention. This paper concludes by discussing the implications of the study for educators and highlighting potential directions for future research. © 2023 by the authors of this article. | O19: International Journal of Engineering Pedagogy | Q19: 10.3991/ijep.v13i8.40853 | R19: Texto completo integro (resolucion de dudosos) | S19: (iii) no automatic sensing
A20: 19 | B20: Incluir | C20: Cumple el alcance: población en edad escolar y contexto doméstico o de aprendizaje remoto | D20: Excluir | E20: Asistente robotico para vocabulario en preescolar; no detecta distraccion | F20: 4 | G20: distracción+niños+contexto+sensado | H20: Scopus | I20: Scopus | J20: 2025 | K20: ARTICLE | L20: Berrezueta-Guzman, Santiago and Dolón-Poza, María | M20: Enhancing Preschool Language Acquisition Through Robotic Assistants: An Evaluation of Effectiveness, Engagement, and Acceptance | N20: Effective early language learning is crucial in education, and finding innovative ways to support it can make a significant difference. This study examines how a robotic assistant can enhance English vocabulary learning for preschool children aged 4 to 6. The study was conducted in two preschools and involved 40 participants split into two groups. Performance assessments were conducted at three stages to evaluate vocabulary acquisition and sentence construction abilities. Results revealed that children interacting with the robot learned 23% more words than those taught through traditional methods, particularly in the early months of exposure. The data analysis, comprising quantitative evaluations of vocabulary learning and qualitative surveys of parents and teachers, highlighted increased engagement, ease of classroom integration, and strong acceptance of the robot. Despite challenges such as student distraction and the need for consistent teacher supervision, the findings demonstrate that robotic assistants complement traditional teaching methods, offering enhanced engagement and improved learning outcomes. © 2013 IEEE. | O20: IEEE Access | P20: Adversarial machine learning; Educational robots; Federated learning; Microrobots; Nanorobots; Robot learning; Teaching; Child engagement and learning; Comparative education method; Early childhood educations; Education methods; Language acquisition; | Q20: 10.1109/access.2025.3538323 | R20: Texto completo (grupos 1-2) | S20: (i) population not of school age
A21: 20 | B21: Incluir | C21: Cumple el alcance: población en edad escolar y contexto doméstico o de aprendizaje remoto | D21: Excluir | E21: Aula STEAM presencial | F21: 4 | G21: distracción+niños+sensado+intervención | H21: Scopus | I21: Scopus | J21: 2025 | K21: CONFERENCE | L21: Van Dinh Sang, Tran and Hoan, Nguyen Ngoc and Tung, Le Chieu and Thu, Nguyen Thi Anh and Van Tuan, Pham | M21: Proposed Machine Learning Approach To Measure Nonverbal Clues-Based Student Satisfaction In STEAM Maker Innovation Space | N21: The integration of artificial intelligence in educational quality management offers significant potential to enhance teaching strategies and student engagement. This study presents the development of a Facial Emotion Recognition System aimed at detecting student satisfaction to improve the learning experience in K-12 STEAM education. The proposed system employs machine learning techniques for Face Recognition Identification and Facial Emotion Recognition, integrated into a teacher-oriented web application to provide real-time insights. A custom dataset of 30 students, spanning elementary to high school levels, was collected at the LYDINC Maker Innovation. This dataset reflects the dynamic and interactive nature of STEAM learning environments, capturing diverse facial expressions and motions. Experimental evaluations reveal the system's efficacy, achieving facial recognition accuracies of 92%, 90%, and 67% across well-matched, medium-mismatched, highly-mismatched test sets, respectively. Emotion recognition achieved an accuracy of 94.54% on the custom dataset and 78% in real-time testing. The satisfaction levels derived from facial emotion analysis were validated against interviews with students and teachers, demonstrating a high correlation with reported satisfaction. These findings highlight the system's potential to enhance teaching quality, create a positive learning environment, and foster the comprehensive development of K-12 STEAM education. © 2025 IEEE. | O21: 2025 IEEE International Conference on Artificial Intelligence and Mechatronics Systems, AIMS 2025 | P21: Computer aided instruction; E-learning; Education computing; Emotion Recognition; Learning algorithms; Learning systems; Machine learning; Psychology computing; Quality management; Statistical tests; Steam; Students; Teaching; Emotion recognition; Fa | Q21: 10.1109/aims66189.2025.11229489 | R21: Texto completo (grupos 1-2) | S21: (ii) setting not domestic or remote
A22: 21 | B22: Incluir | C22: Cumple el alcance: población en edad escolar y contexto doméstico o de aprendizaje remoto | D22: Excluir | E22: Laboratorio con realidad virtual; poblacion universitaria | F22: 4 | G22: distracción+niños+contexto+intervención | H22: WoS | I22: WoS | J22: 2023 | K22: Article | L22: Hu, RH; Hui, ZH; Li, YF; Guan, JQ | M22: Research on Learning Concentration Recognition with Multi-Modal Features in Virtual Reality Environments | N22: Learning concentration, as a crucial factor influencing learning outcomes, provides the basis for learners' self-regulation and teachers' instructional adjustments and intervention decisions. However, the current research on learning concentration recognition lacks the integration of cognitive, emotional, and behavioral features, and the integration of interaction and vision data for recognition requires further exploration. The way data are collected in a head-mounted display differs from that in a traditional classroom or online learning. Therefore, it is vital to explore a recognition method for learning concentration based on multi-modal features in VR environments. This study proposes a multi-modal feature integration-based learning concentration recognition method in VR environments. It combines interaction and vision data, including measurements of interactive tests, text, clickstream, pupil facial expressions, and eye gaze data, to measure learners' concentration in VR environments in terms of cognitive, emotional, and behavioral representation. The experimental results demonstrate that the proposed method, which integrates interaction and vision data to comprehensively represent the cognitive, emotional, and behavioral dimensions of learning concentration, outperforms single-dimensional and single-type recognition results in terms of accuracy. Additionally, it was found that learners with higher concentration levels achieve better learning outcomes, and learners' perceived sense of immersion is an important factor influencing their concentration. | O22: SUSTAINABILITY | Q22: 10.3390/su151511606 | R22: Texto completo (grupos 1-2) | S22: (i) population not of school age
A23: 22 | B23: Incluir | C23: Cumple el alcance: población en edad escolar y contexto doméstico o de aprendizaje remoto | D23: Excluir | E23: Alfabetizacion alimentaria en preescolares; no aborda distraccion | F23: 3 | G23: distracción+niños+sensado | H23: ACM | I23: ACM | J23: 2024 | K23: inproceedings | L23: Cai, Xueyan and Jin, Kecheng and Shi, Shang and Huang, Shichao and Huang, Ouying and Wang, Xiaodong and Cheng, Jiahao and Lin, Weijia and Yao, Jiayu and Hu, Yuqi and Zhang, Chao and Yao, Cheng | M23: "See, Hear, Touch, Smell, and,...Eat!": Helping Children Self-Improve Their Food Literacy and Eating Behavior through a Tangible Multi-Sensory Puzzle Game | N23: Picky eating behavior is common in preschoolers and has been linked to a lack of food literacy with support from certain research. Recent research has focused on interventions for children’s mealtime behaviors which can lead to distraction and neglect of food literacy learning. We propose FeastyMaze, a tangible and multi-sensory interactive puzzle game for young children to improve eating behavior. With the Five-color Diet Theory, our approach enables children to actively learn about food nutrition and balanced diets. To evaluate the effectiveness and acceptability of FeastyMaze, we conducted a user study with preschoolers (N = 12) who exhibited picky eating behaviors. The results showed that it effectively increased children’s familiarity and understanding of food knowledge, built positive attitudes towards previously disliked foods, and had the potential to improve their eating behavior. | O23: Proceedings of the 23rd Annual ACM Interaction Design and Children Conference | P23: CCI, food literacy education, games, multi-sensory interaction, puzzles, tangible user interface | Q23: 10.1145/3628516.3655801 | R23: Texto completo (grupos 1-2) | S23: (i) population not of school age
A24: 23 | B24: Incluir | C24: Cumple el alcance: población en edad escolar y contexto doméstico o de aprendizaje remoto | D24: Excluir | E24: Prediccion de rendimiento con datos de plataforma | F24: 3 | G24: distracción+niños+sensado | H24: Scopus | I24: Scopus | J24: 2024 | K24: CONFERENCE | L24: Anistyasari, Yeni and Hidayati, Shintami C. and Ekohariadi | M24: A Tree-Based Model for Predicting Student Achievement in Online Learning Environments | N24: An important instrument of academic performance is student engagement in online learning. This work built a prediction model based on decision trees to find elements influencing student engagement in online learning settings. Examined were involvement, interaction, responsiveness to criticism, and academic performance. Examining the correlations between these factors and student involvement levels using decision trees revealed According to the findings, student involvement was highly predicted by participation and interaction; followed by responsiveness to criticism and academic performance. The approach reveals great accuracy in estimating engagement levels, which let teachers find children who may need certain interventions or more help. Using this approach, teachers and designers of learning environments may be more aggressive in raising student involvement by means of more focused approaches. These results highlight the necessity of a data-driven strategy to increase the efficacy of online learning as well as provide insightful analysis for the creation of more flexible and sensitive educational technology suited for student requirements. © 2024 IEEE. | O24: 2024 7th International Conference on Vocational Education and Electrical Engineering: Charting the Course of Artificial Technology in Sustainable Society, ICVEE 2024 | P24: Adversarial machine learning; Collaborative learning; Digital elevation model; Federated learning; Prediction models; Academic performance; Online learning; Online learning environment; Predictive models; Student achievement; Student engagement; Stud | Q24: 10.1109/icvee63912.2024.10823659 | R24: Texto completo (grupos 1-2) | S24: (iii) no automatic sensing
A25: 24 | B25: Incluir | C25: Cumple el alcance: población en edad escolar y contexto doméstico o de aprendizaje remoto | D25: Excluir | E25: Aula presencial; panel para docentes, no monitorizacion del nino en el hogar | F25: 3 | G25: distracción+niños+sensado | H25: Scopus | I25: Scopus|WoS | J25: 2021 | K25: ARTICLE | L25: Gupta, Ankit and Menon, Neeraj and Lee, William and Rebelsky, William and Allesio, Danielle and Murray, Tom and Woolf, Beverly and Whitehill, Jacob and Arroyo, Ivon | M25: Affective Teacher Tools: Affective Class Report Card and Dashboard | N25: While using online learning software, students demonstrate many reactions, various levels of engagement, and emotions (e.g. confusion, excitement, frustration). Having such information automatically accessible to teachers (or digital tutors) can aid in understanding how students progress and suggest when and who needs further assistance. We developed the Affective Teacher Tools, a report card and dashboard that present teachers measures of students’ engagement and affective states as they use an online tutoring system, MathSpring.org, which supports students as they practice mathematics problem-solving at the middle school level. We conducted two development and research studies – one that assesses teachers perception of the affective report card and a second study that assesses a live affective dashboard, which senses students’ affect and performance in a live class that is using MathSpring. We use computer vision techniques to measure students’ engagement and affective states from their facial expressions while they use the tutoring system. In this paper, we summarize both the report card and affective dashboard, the research studies and results, and we also discuss implications, and future planned experiments for the next phase of this research. © 2021, Springer Nature Switzerland AG. | O25: Lecture Notes in Computer Science (including subseries Lecture Notes in Artificial Intelligence and Lecture Notes in Bioinformatics) | P25: Computer aided instruction; Intelligent vehicle highway systems; Affect; Affective state; Engagement; Intelligent tutoring; Intelligent tutoring system; Report cards; Research studies; Student engagement; Teachers'; Tutoring system; Students | Q25: 10.1007/978-3-030-78292-4_15 | R25: Texto completo (grupos 1-2) | S25: (i) population not of school age
A26: 25 | B26: Incluir | C26: Cumple el alcance: población en edad escolar y contexto doméstico o de aprendizaje remoto | D26: Excluir | E26: Aprendizaje fuera del aula, pero sin sensado: modela engagement con registros de uso del sistema; no declara edades | F26: 3 | G26: distracción+niños+sensado | H26: Scopus | I26: Scopus | J26: 2020 | K26: ARTICLE | L26: Hershcovits, Haviv and Vilenchik, Dan and Gal, Kobi | M26: Modeling Engagement in Self-Directed Learning Systems Using Principal Component Analysis | N26: This paper studies students engagement in e-learning environments in which students work independently and solve problems without external supervision. We propose a new method to infer engagement patterns of users in such self-directed environments. We view engagement as a continuous process in time, measured along chosen axes that are derived from student data in the system using unsupervised learning (Principal Component Analysis). We construct a trajectory of user activity by projecting the user's scores along the selected PCs at regular time intervals. This approach is applied to a popular e-learning software for K12 math education that is used by thousands of students worldwide. We identify cohorts of users according to the way their trajectory changes over time (e.g., monotone up, monotone down, and constant). Each of the cohorts exhibits distinct behavioral dynamics and differed substantially in the amount of time users spent in the e-learning system. Specifically, one cohort included students that dropped out of the system after choosing very difficult problems that they were not able to complete, while another cohort included students users that chose more diverse problems and stayed longer in the system. In future work, these results can be used by teachers or intelligent tutors to track students' engagement in the system and decide whether and how to intervene. © 2008-2011 IEEE. | O26: IEEE Transactions on Learning Technologies | P26: Computer aided instruction; E-learning; Educational technology; Job analysis; Machine learning; Students; Time series analysis; Trajectories; Unsupervised learning; Behavioral dynamics; Continuous process; E-learning environment; Electronic learning; | Q26: 10.1109/tlt.2019.2922902 | R26: Texto completo integro (resolucion de dudosos) | S26: (ii) setting not domestic or remote
